Workbook

Sheet Kost
A2: No | B2: Nama Kost | C2: Nama Pemilik Kost | D2: Alamat Kost | E2: No tlpn Pemilik Kost | F2: Jenis Kost | G2: Harga | H2: Fasiltas | I2: Jenis Listrik | J2: Jenis Air | K2: Luas Kamar | L2: Keamanan | M2: Lokasi Pendukung | N2: Batas Jam Malam | O2: Transportasi
A3: 1 | B3: Pondok Harmony 1 | C3: Olan | D3: Jalan Sahabat 3 no 15 | E3: +6285926084686 | G3: Rp 800.000 | H3: Spring Bed, Kipas, Lemari, Meja, Wc Dalam, Dapur Dalam, wifi | I3: Token | J3: Pembayaran Awal dan Sumur Bor | K3: 3x4 | L3: CCTV sama Penjaga | M3: Laundry, tempat makan, Masjid Fotocopy ATK, Warung | N3: 22,00 | O3: Angkutan Umum, Motor, Mobil
A4: 2 | B4: Pondok Harmony 2 | C4: Olan | D4: Jalan Sahabat 3 no 15 | E4: +6285926084686 | G4: Rp 1.200.000 | H4: Spring Bed Kipas, Lemari, Meja, Wc Dalam, Dapur Dalam, AC, Wifi | I4: Token | J4: Pembayaran Awal dan Sumur Bor | K4: 3x4 | L4: CCTV sama penjaga | M4: Laundry, tempat makan, Masjid Fotocopy ATK, Warung | N4: Smart Lock berbasis Kunci Pagar | O4: Angkutan Umum, Motor, Mobil
A5: 3 | B5: Pondok Harmony 3 | C5: Olan | E5: +6285926084686 | G5: Rp 1.500.000 | H5: Spring Bed Kipas, Lemari, Meja, Wc Dalam, Dapur Dalam, AC, Wifi | I5: Token | J5: Pembayaran Awal dan Sumur Bor | K5: 4x5 | L5: CCTV sama penjaga | M5: Laundry, tempat makan, Masjid Fotocopy ATK, Warung | O5: Angkutan Umum, Motor, Mobil
A6: 4 | B6: Pondiok Hikmah Jaya 2 | C6: Mardawati | D6: Jalan Sahabat 3 no 18 | E6: +6285323006053 | F6: Putri | G6: 8 Juta Per Tahun | H6: Tempat tidur, Spring Bed, Lemari | I6: PLN dan Perbulan | J6: Pembayaran Awal dan Sumur Bor | K6: 5 x4 | L6: CCTV, Penjaga | M6: Laundry, tempat makan, Masjid Fotocopy ATK, Warung | N6: 22, 00 dan kunci | O6: Angkutan Umum, Motor, Mobil
A7: 5 | B7: KF02 | C7: Kasman Sudirman | D7: Jalan Sahabat Raya no 27 | E7: Tidak di Publish | F7: Umum | G7: Rp 1.500.000 | H7: Spring Bed, Lemari, Meja, Exhaust, AC | I7: Token dan Prabayar | J7: Pembayaran Awal dan Sumur Bor | K7: 3x4 | L7: CCTV sama penjaga | M7: Laundry, tempat makan, Masjid Fotocopy ATK, Warung | N7: Bebas, Kunci Pagar | O7: Angkutan Umum, Motor, Mobil
A8: 6 | B8: Pondok Mama | C8: Ibu Sakia sama Bapak Anto | D8: Jalan Sahabat 3 no 15 | E8: +6285399929977, +6282124347558 | F8: Putri | G8: Rp. 1.500.000 | H8: Ac, Spring Bed, Lemari, Wc Dalam, wifi, electric hoist | I8: Token | J8: Pembayaran Awal dan Sumur Bor | K8: 4x3 | L8: CCTV sama penjaga | M8: Laundry, tempat makan, Masjid Fotocopy ATK, Warung | N8: Bebas | O8: Angkutan Umum, Motor, Mobil

Sheet Ressponden
A1: Kruteria | B1: Bobot | D1: no
A2: Biaya | B2: =AVERAGE(B15,E15,H15,K15,N15) -> 18.4 | D2: 1
A3: Fasilitas | B3: =AVERAGE(B16,E16,H16,K16,N16) -> 11.2 | D3: 2
A4: Luas Kamar | B4: =AVERAGE(B17,E17,H17,K17,N17) -> 10.6 | D4: 3
A5: Jarak | B5: =AVERAGE(B18,E18,H18,K18,N18) -> 11.6 | D5: 4
A6: Keamanan | B6: =AVERAGE(B19,E19,H19,K19,N19) -> 14.2 | D6: 5
A7: Batas Jam Malam | B7: =AVERAGE(B20,E20,H20,K20,N20) -> 7.2 | D7: 6
A8: linkungan pendukung | B8: =AVERAGE(B21,E21,H21,K21,N21) -> 7 | D8: 7
A9: Jenis air | B9: =AVERAGE(B22,E22,H22,K22,N22) -> 6 | D9: 8
A10: jenis listrik | B10: =AVERAGE(B23,E23,H23,K23,N23) -> 7 | D10: 9
A11: jalur transaportasi | B11: =AVERAGE(B24,E24,H24,K24,N24) -> 6.8 | D11: 10
B12: =SUM(B2:B11) -> 100
A13: R1 = Abid | D13: R2 = Epo | G13: R3 = Irwan | J13: R4 = Reyhan
A14: Kruteria | B14: Bobot | D14: Kruteria | E14: Bobot | G14: Kruteria | H14: Bobot | J14: Kruteria | K14: Bobot | M14: Kruteria | N14: Bobot
A15: Biaya | B15: 22 | D15: Biaya | E15: 25 | G15: Biaya | H15: 20 | J15: Biaya | K15: 13 | M15: Biaya | N15: 12
A16: Fasilitas | B16: 18 | D16: Fasilitas | E16: 8 | G16: Fasilitas | H16: 10 | J16: Fasilitas | K16: 10 | M16: Fasilitas | N16: 10
A17: Luas Kamar | B17: 12 | D17: Luas Kamar | E17: 10 | G17: Luas Kamar | H17: 15 | J17: Luas Kamar | K17: 5 | M17: Luas Kamar | N17: 11
A18: Jarak | B18: 8 | D18: Jarak | E18: 20 | G18: Jarak | H18: 15 | J18: Jarak | K18: 5 | M18: Jarak | N18: 10
A19: Keamanan | B19: 10 | D19: Keamanan | E19: 15 | G19: Keamanan | H19: 6 | J19: Keamanan | K19: 20 | M19: Keamanan | N19: 20
A20: Batas Jam Malam | B20: 8 | D20: Batas Jam Malam | E20: 2 | G20: Batas Jam Malam | H20: 6 | J20: Batas Jam Malam | K20: 10 | M20: Batas Jam Malam | N20: 10
A21: linkungan pendukung | B21: 6 | D21: linkungan pendukung | E21: 5 | G21: linkungan pendukung | H21: 10 | J21: linkungan pendukung | K21: 7 | M21: linkungan pendukung | N21: 7
A22: Jenis air | B22: 5 | D22: Jenis air | E22: 5 | G22: Jenis air | H22: 5 | J22: Jenis air | K22: 10 | M22: Jenis air | N22: 5
A23: jenis listrik | B23: 5 | D23: jenis listrik | E23: 5 | G23: jenis listrik | H23: 5 | J23: jenis listrik | K23: 10 | M23: jenis listrik | N23: 10
A24: jalur transaportasi | B24: 6 | D24: jalur transaportasi | E24: 5 | G24: jalur transaportasi | H24: 8 | J24: jalur transaportasi | K24: 10 | M24: jalur transaportasi | N24: 5
B25: =SUM(B15:B24) -> 100 | E25: =SUM(E15:E24) -> 100 | H25: =SUM(H15:H24) -> 100 | K25: =SUM(K15:K24) -> 100 | N25: =SUM(N15:N24) -> 100

Sheet Bobot Kriteria
A1: Kruteria | B1: Bobot | C1: Simbol | E1: Sub Kriteria | U1: Lingkungan Pendukung
A2: Biaya | B2: =Ressponden!B2 -> 18.4 | C2: C1 | U2: Tempat Makan
A3: Fasilitas | B3: =Ressponden!B3 -> 11.2 | C3: C2 | E3: C1 | F3: Biaya | I3: C4 | J3: Jarak | M3: C7 | N3: Lingkungan Pendukung | U3: Atk
A4: Luas Kamar | B4: =Ressponden!B4 -> 10.6 | C4: C3 | F4: Nilai | G4: Bobot | J4: Nilai | K4: Bobot | N4: Nilai | O4: Bobot | U4: warung
A5: Jarak | B5: =Ressponden!B5 -> 11.6 | C5: C4 | F5: ≤ Rp 700.000 – Rp 900.000 | G5: 1 | J5: < 500 m | K5: 1 | N5: 1 | O5: 1 | U5: Ibadah
A6: Keamanan | B6: =Ressponden!B6 -> 14.2 | C6: C5 | F6: > Rp 900.000 – Rp 1.300.000 | G6: 2 | J6: >= 500 m - 1km | K6: 2 | N6: 2 | O6: 2 | U6: Laundry
A7: Batas Jam Malam | B7: =Ressponden!B7 -> 7.2 | C7: C6 | F7: > Rp 1.300.000 – Rp 1.600.000 | G7: 3 | J7: >= 1km - 2km | K7: 3 | N7: 3 | O7: 3
A8: linkungan pendukung | B8: =Ressponden!B8 -> 7 | C8: C7 | F8: > Rp 1.600.000 – Rp 2.000.000 | G8: 4 | J8: >= 2km - 3km | K8: 4 | N8: 4 | O8: 4 | U8: Fasilitas
A9: Jenis air | B9: =Ressponden!B9 -> 6 | C9: C8 | F9: > Rp 2.000.000 | G9: 5 | J9: > 3km | K9: 5 | N9: 5 | O9: 5 | U9: Spring Bed
A10: jenis listrik | B10: =Ressponden!B10 -> 7 | C10: C9 | U10: Kamar mandi
A11: jalur transaportasi | B11: =Ressponden!B11 -> 6.8 | C11: C10 | E11: C2 | F11: Fasilitas | I11: C5 | J11: Keamanan | M11: C8 | N11: Jenis Air | Q11: C10 | R11: Jalur Transportasi | U11: Meja
B12: =Ressponden!B12 -> 100 | F12: Nilai | G12: Bobot | J12: Nilai | K12: Bobot | N12: Nilai | O12: Bobot | R12: Nilai | S12: Bobot | U12: Wifi
F13: <=2 | G13: 1 | J13: Tidak ada | K13: 1 | N13: token | O13: 1 | R13: Jalan Kaki | S13: 1 | U13: Tempat parkir
F14: >=2 - 4 | G14: 2 | J14: Smart Lock | K14: 2 | N14: Pascabayar/bulanan | O14: 2 | R14: Motor | S14: 2 | U14: Lemari
F15: >=4 - 6 | G15: 3 | J15: Satpam | K15: 3 | N15: Pada Waktu Sewa | O15: 3 | R15: Mobil | S15: 3 | U15: Wifi
A16: Kruteria | B16: Kategori | F16: >=6 - 8 | G16: 4 | J16: CCTV | K16: 4 | R16: Angkutan Umum | S16: 4 | U16: Dapur
A17: Biaya | B17: Cost | C17: Semakin Rendah semakin Baik | F17: >=10 | G17: 5 | J17: Satpam, CCTV, SmartLock | K17: 5 | U17: Ac
A18: Fasilitas | B18: Benefit | C18: Semakin Tinggi semakin Baik | M18: C9 | N18: Jenis Listrik | U18: Kipas
A19: Luas Kamar | B19: Benefit | C19: Semakin Tinggi semakin Baik | N19: Nilai | O19: Bobot
A20: Jarak | B20: Cost | C20: Semakin Rendah semakin Baik | N20: token | O20: 1
A21: Keamanan | B21: Benefit | C21: Semakin Tinggi semakin Baik | E21: C3 | F21: Luas Kamar | I21: C6 | J21: Batas Jam Malam | N21: Pascabayar/bulanan | O21: 2
A22: Batas Jam Malam | B22: Cost | C22: Semakin Rendah semakin Baik | F22: Nilai | G22: Bobot | J22: Nilai | K22: Bobot | N22: Pada Waktu Sewa | O22: 3
A23: linkungan pendukung | B23: Benefit | C23: Semakin Tinggi semakin Baik | F23: < 7M^2 | G23: 1 | J23: 21,00 | K23: 1
A24: Jenis air | B24: Benefit | C24: Semakin Tinggi semakin Baik | F24: >= 7M^2 - 10M^2 | G24: 2 | J24: 22,00 | K24: 2
A25: jenis listrik | B25: Benefit | C25: Semakin Tinggi semakin Baik | F25: >= 10M^2 - 14M^2 | G25: 3 | J25: 23,00 - 24,00 | K25: 3
A26: jalur transaportasi | B26: Benefit | C26: Semakin Tinggi semakin Baik | F26: >= 14M^2 - 18M^2 | G26: 4 | J26: beri kunci | K26: 4
F27: > 18M^2 | G27: 5 | J27: 24 jam terbuka | K27: 5

Sheet Studi Kasus
A1: 1. Menentukan Kriteria | E1: 4. Menentukan Crips | U1: Lingkungan Pendukung
A2: Ci | B2: Keterangan | U2: Tempat Makan
A3: C1 | B3: Biaya | E3: C1 | F3: Biaya | I3: C4 | J3: Jarak | M3: C7 | N3: Lingkungan Pendukung | U3: Atk
A4: C2 | B4: Fasilitas | F4: Nilai | G4: Bobot | J4: Nilai | K4: Bobot | N4: Nilai | O4: Bobot | U4: warung
A5: C3 | B5: Luas Kamar | F5: ≤ Rp 700.000 – Rp 900.000 | G5: 1 | J5: < 500 m | K5: 1 | N5: <=1 | O5: 1 | U5: Ibadah
A6: C4 | B6: Jarak | F6: >= Rp 900.000 – Rp 1.300.000 | G6: 2 | J6: >= 500 m - 1km | K6: 2 | N6: 2 | O6: 2 | U6: Laundry
A7: C5 | B7: Keamanan | F7: >= Rp 1.300.000 – Rp 1.600.000 | G7: 3 | J7: >= 1km - 2km | K7: 3 | N7: 3 | O7: 3
A8: C6 | B8: Batas Jam Malam | F8: >= Rp 1.600.000 – Rp 2.000.000 | G8: 4 | J8: >= 2km - 3km | K8: 4 | N8: 4 | O8: 4
A9: C7 | B9: linkungan pendukung | F9: > Rp 2.000.000 | G9: 5 | J9: > 3km | K9: 5 | N9: 5 | O9: 5
A10: C8 | B10: Jenis air
A11: C9 | B11: jenis listrik | E11: C2 | F11: Fasilitas | I11: C5 | J11: Keamanan | M11: C8 | N11: Jenis Air | Q11: C10 | R11: Jalur Transportasi
A12: C10 | B12: jalur transaportasi | F12: Nilai | G12: Bobot | J12: Nilai | K12: Bobot | N12: Nilai | O12: Bobot | R12: Nilai | S12: Bobot
F13: <=2 | G13: 1 | J13: Tidak ada | K13: 1 | N13: token | O13: 1 | R13: Jalan Kaki | S13: 1
F14: >=2 - 4 | G14: 2 | J14: Smart Lock | K14: 2 | N14: Pascabayar/bulanan | O14: 2 | R14: Motor | S14: 2
A15: 2. Menentukan Bobot dari Kriteria | F15: >=4 - 6 | G15: 3 | J15: Satpam | K15: 3 | N15: Pada Waktu Sewa | O15: 3 | R15: Mobil | S15: 3
F16: >=6 - 8 | G16: 4 | J16: CCTV | K16: 4
A17: Ci | B17: W | C17: Bobot | F17: >=10 | G17: 5 | J17: Satpam, CCTV, SmartLock | K17: 5
A18: C1 | B18: W1 | C18: =Ressponden!B2 -> 18.4 | M18: C9 | N18: Jenis Listrik | U18: Fasilitas
A19: C2 | B19: W2 | C19: =Ressponden!B3 -> 11.2 | N19: Nilai | O19: Bobot | U19: Spring Bed
A20: C3 | B20: W3 | C20: =Ressponden!B4 -> 10.6 | N20: token | O20: 1 | U20: Kamar mandi
A21: C4 | B21: W4 | C21: =Ressponden!B5 -> 11.6 | E21: C3 | F21: Luas Kamar | I21: C6 | J21: Batas Jam Malam | N21: Pascabayar/bulanan | O21: 2 | U21: Meja
A22: C5 | B22: W5 | C22: =Ressponden!B6 -> 14.2 | F22: Nilai | G22: Bobot | J22: Nilai | K22: Bobot | N22: Pada Waktu Sewa | O22: 3 | U22: Wifi
A23: C6 | B23: W6 | C23: =Ressponden!B7 -> 7.2 | F23: < 7M^2 | G23: 1 | J23: 21,00 | K23: 1 | U23: Tempat parkir
A24: C7 | B24: W7 | C24: =Ressponden!B8 -> 7 | F24: >= 7M^2 - 10M^2 | G24: 2 | J24: 22,00 | K24: 2 | U24: Lemari
A25: C8 | B25: W8 | C25: =Ressponden!B9 -> 6 | F25: >= 10M^2 - 14M^2 | G25: 3 | J25: 23,00 - 24,00 | K25: 3 | U25: kursi
A26: C9 | B26: W9 | C26: =Ressponden!B10 -> 7 | F26: >= 14M^2 - 18M^2 | G26: 4 | J26: beri kunci | K26: 4 | U26: Dapur
A27: C10 | B27: W10 | C27: =Ressponden!B11 -> 6.8 | F27: > 18M^2 | G27: 5 | J27: 24 jam terbuka | K27: 5 | U27: Ac
C28: =Ressponden!B12 -> 100 | U28: Kipas
A30: 3. Menentukan Atribut Kriteria
A32: Ci | B32: Atribut
A33: C1 | B33: Cost
A34: C2 | B34: Benefit
A35: C3 | B35: Benefit
A36: C4 | B36: Cost
A37: C5 | B37: Benefit
A38: C6 | B38: Cost
A39: C7 | B39: Benefit
A40: C8 | B40: Benefit
A41: C9 | B41: Benefit
A42: C10 | B42: Benefit
...

Sheet Hasil Bab 4
A1: 1. Menentukan Kriteria | E1: 4. Menentukan Crips | U1: Lingkungan Pendukung
U2: Tempat Makan
A3: C1 | B3: Biaya | E3: C1 | F3: Biaya | I3: C4 | J3: Jarak | M3: C7 | N3: Lingkungan Pendukung | U3: Atk
A4: C2 | B4: Fasilitas | F4: Nilai | G4: Bobot | J4: Nilai | K4: Bobot | N4: Nilai | O4: Bobot | U4: warung
A5: C3 | B5: Luas Kamar | F5: ≤ Rp 700.000 – Rp 900.000 | G5: 1 | J5: < 500 m | K5: 1 | N5: 1 | O5: 1 | U5: Ibadah
A6: C4 | B6: Jarak | F6: >= Rp 900.000 – Rp 1.300.000 | G6: 2 | J6: >= 500 m - 1km | K6: 2 | N6: 2 | O6: 2 | U6: Laundry
A7: C5 | B7: Keamanan | F7: >= Rp 1.300.000 – Rp 1.600.000 | G7: 3 | J7: >= 1km - 2km | K7: 3 | N7: 3 | O7: 3
A8: C6 | B8: Batas Jam Malam | F8: >= Rp 1.600.000 – Rp 2.000.000 | G8: 4 | J8: >= 2km - 3km | K8: 4 | N8: 4 | O8: 4 | U8: Fasilitas
A9: C7 | B9: linkungan pendukung | F9: > Rp 2.000.000 | G9: 5 | J9: > 3km | K9: 5 | N9: 5 | O9: 5 | U9: Spring Bed
A10: C8 | B10: Jenis air | U10: Kamar mandi
A11: C9 | B11: jenis listrik | E11: C2 | F11: Fasilitas | I11: C5 | J11: Keamanan | M11: C8 | N11: Jenis Air | Q11: C10 | R11: Jalur Transportasi | U11: Meja
A12: C10 | B12: jalur transaportasi | F12: Nilai | G12: Bobot | J12: Nilai | K12: Bobot | N12: Nilai | O12: Bobot | R12: Nilai | S12: Bobot | U12: Wifi
F13: <=2 | G13: 1 | J13: Tidak ada | K13: 1 | N13: token | O13: 1 | R13: Jalan Kaki | S13: 1 | U13: Tempat parkir
F14: >=2 - 4 | G14: 2 | J14: Smart Lock | K14: 2 | N14: Pascabayar/bulanan | O14: 2 | R14: Motor | S14: 2 | U14: Lemari
A15: 2. Menentukan Bobot dari Kriteria | F15: >=4 - 6 | G15: 3 | J15: Satpam | K15: 3 | N15: Pada Waktu Sewa | O15: 3 | R15: Mobil | S15: 3 | U15: Wifi
F16: >=6 - 8 | G16: 4 | J16: CCTV | K16: 4 | R16: Angkutan Umum | S16: 4 | U16: Dapur
A17: Ci | B17: W | C17: Bobot | F17: >=10 | G17: 5 | J17: Satpam, CCTV, SmartLock | K17: 5 | U17: Ac
A18: C1 | B18: W1 | C18: =Ressponden!B2 -> 18.4 | M18: C9 | N18: Jenis Listrik | U18: Kipas
A19: C2 | B19: W2 | C19: =Ressponden!B3 -> 11.2 | N19: Nilai | O19: Bobot
A20: C3 | B20: W3 | C20: =Ressponden!B4 -> 10.6 | N20: token | O20: 1
A21: C4 | B21: W4 | C21: =Ressponden!B5 -> 11.6 | E21: C3 | F21: Luas Kamar | I21: C6 | J21: Batas Jam Malam | N21: Pascabayar/bulanan | O21: 2
A22: C5 | B22: W5 | C22: =Ressponden!B6 -> 14.2 | F22: Nilai | G22: Bobot | J22: Nilai | K22: Bobot | N22: Pada Waktu Sewa | O22: 3
A23: C6 | B23: W6 | C23: =Ressponden!B7 -> 7.2 | F23: < 7M^2 | G23: 1 | J23: 21,00 | K23: 1
A24: C7 | B24: W7 | C24: =Ressponden!B8 -> 7 | F24: >= 7M^2 - 10M^2 | G24: 2 | J24: 22,00 | K24: 2
A25: C8 | B25: W8 | C25: =Ressponden!B9 -> 6 | F25: >= 10M^2 - 14M^2 | G25: 3 | J25: 23,00 - 24,00 | K25: 3
A26: C9 | B26: W9 | C26: =Ressponden!B10 -> 7 | F26: >= 14M^2 - 18M^2 | G26: 4 | J26: beri kunci | K26: 4
A27: C10 | B27: W10 | C27: =Ressponden!B11 -> 6.8 | F27: > 18M^2 | G27: 5 | J27: 24 jam terbuka | K27: 5
C28: =Ressponden!B12 -> 100
A30: 3. Menentukan Atribut Kriteria
A32: Ci | B32: Atribut
A33: C1 | B33: Cost
A34: C2 | B34: Benefit
A35: C3 | B35: Benefit
A36: C4 | B36: Cost
A37: C5 | B37: Benefit
A38: C6 | B38: Cost
A39: C7 | B39: Benefit
A40: C8 | B40: Benefit
A41: C9 | B41: Benefit
A42: C10 | B42: Benefit
...
